Workbook

Sheet 1. BRIEFING
A2: CLIENTE: | B2: - | F2: SUA LOGO AQUI!
A3: ARQ.: | B3: -
A4: OBRA: | B4: -
A5: PLANILHA DE BRIEFING COM CLIENTE E AUTOR DO PROJETO
A6: ITEM | B6: DESCRIÇÃO | C6: UND | D6: QNTD | E6: MEM CAL | F6: OBSERVAÇÕES
A8: 1 | B8: SERVIÇOS ADIMINSTRATIVOS
A9: 1.1 | B9: ADMINISTRAÇÃO DE OBRA | C9: MES | D9: =E9 -> 1 | E9: 1
A10: 1.2 | B10: TRANSPORTE E ALIMENTAÇÃO EQP ADM | C10: MES | D10: =E10 -> 1 | E10: 1
A11: 1.3 | B11: ART DE EXECUÇÃO DA OBRA | C11: UN | D11: =E11 -> 1 | E11: 1
A12: 1.4 | B12: ISOLAMENTO/PROTEÇÃO COM LONA/PLÁSTICO BOLHA | C12: VB | D12: =E12 -> 1 | E12: 1
A13: 1.5 | B13: MOBILIZAÇÃO E DESMOBILIZAÇÃO | C13: UN | D13: =E13 -> 1 | E13: 1
A14: 2 | B14: DEMOLIÇÃO E RETIRADA
A15: 2.1 | B15: DEMOLIÇÃO DE ALVENARIA DE VEDAÇÃO | C15: M² | D15: =E15 -> 1,00 | E15: 1,00
A16: 2.2 | B16: REMOÇÃO DE BANCADAS EM GRANITO | C16: UND | D16: =E16 -> 1,00 | E16: 1,00
A17: 2.3 | B17: REMOÇÃO DE LOUÇAS E METAIS | C17: VB | D17: =E17 -> 1,00 | E17: 1,00
A18: 2.4 | B18: REMOÇÃO DE PORTAS INTERNAS EM MADEIRA | C18: UN | D18: =E18 -> 1,00 | E18: 1,00
A19: 2.5 | B19: DEMOLIÇÃO DE REVESTIMENTO CERÂMICO EM PAREDE | C19: M² | D19: =E19 -> 1,00 | E19: 1,00
A20: 2.6 | B20: DEMOLIÇÃO DE REVESTIMENTO CERÂMICO EM PISO | C20: M² | D20: =E20 -> 1,00 | E20: 1,00
A21: 2.7 | B21: DEMOLIÇÃO DE FORRO EM GESSO/PVC | C21: M² | D21: =E21 -> 1,00 | E21: 1,00
A22: 2.8 | B22: REMOÇÃO DE LUMINÁRIAS INTERNAS (FORRO) | C22: UN | D22: =E22 -> 1,00 | E22: 1,00
A23: 2.9 | B23: REMOÇÃO DOS ENTULHOS POR SACOS E CARRO PEQUENO | C23: UN | D23: =E23 -> 1,00 | E23: 1,00
A24: 3 | B24: SERVIÇO EM ALVENARIA
A25: 3.1 | B25: ASSENTAMENTO DE ALVENARIA DE VEDAÇÃO | C25: M² | D25: =E25 -> 1 | E25: 1
A26: 3.2 | D26: =E26 -> 0
A27: 3.3 | D27: =E27 -> 0
A28: 3.4 | D28: =E28 -> 0
A29: 4 | B29: INSTALAÇÃO HIDRÁULICA
A30: 4.1 | B30: INSTALAÇAO DE PONTO DE ÁGUA FRIA | C30: UN | D30: =E30 -> 10 | E30: 10
A31: 4.2 | B31: INSTALAÇÃO DE PONTO DE ESGOTO 50 MM | C31: UN | D31: =E31 -> 1 | E31: 1
A32: 4.3 | B32: RELOCAÇÃO DE PONTO DE ESGOTO 100 MM | C32: UN | D32: =E32 -> 1 | E32: 1
A33: 4.4 | B33: INSTALAÇÃO DE PONTO DE REGISTRO DE GAVETA | C33: UN | D33: =E33 -> 1 | E33: 1
A34: 4.5 | B34: INSTALAÇÃO DE PONTO DE REGISTRO DE PRESSÃO | C34: UN | D34: =E34 -> 1 | E34: 1
A35: 5 | B35: INSTALAÇÃO ELÉTRICA
A36: 5.1 | B36: INSTALAÇÃO DE INFRAESTRUTURA PARA TOMADA E ILUMINAÇÃO | C36: UN | D36: =E36 -> 1 | E36: 1
A37: 5.2 | B37: INSTALAÇÃO DE CABEAMENTO PARA PONTOS DE TOMADAS | C37: UN | D37: =E37 -> 1 | E37: 1
A38: 5.3 | B38: INSTALAÇÃO DE CABEAMENTO PARA PONTOS DE ILUMINAÇÃO | C38: UN | D38: =E38 -> 1 | E38: 1
A39: 5.4 | B39: REISNTALAÇÃO DE QUADRO DE DISTRIBUIÇÃO (ADEQUAÇÃO) | C39: VB | D39: =E39 -> 1 | E39: 1
A40: 5.5 | B40: INSTALAÇÃO DE INFRAESTRUTURA PARA PONTOS DE REDE/ANTENA/CAMERA/SOM | C40: UN | D40: =E40 -> 1 | E40: 1
A41: 6 | B41: INSTALAÇÃO DE EQUIPAMENTOS
A42: 6.1 | B42: INSTALAÇÃO DE INFRA PARA AR CONDICIONADO | C42: UN | D42: =E42 -> 1 | E42: 1
...

Sheet 2. LEV QNT
B1: LEVANTAMENTO DE QUANTITATIVOS EM PAREDES
C2: MEDIDAS | F2: ALVENARIA | I2: PINTURA | L2: REVESTIMENTO (M²)
B3: AMBIENTE | C3: PERIMETRO | D3: PÉ DIREITO | E3: DESCONTOS | F3: ALVENARIA (M²) | G3: CHAPISCO (M²) | H3: REBOCO (M²) | I3: SELADOR (M²) | J3: MASSA CORRIDA (M²) | K3: PINTURA (M²) | L3: PORCELANTO | M3: CERÂMICA
B4: SALA | F4: =(C4*D4)-E4 -> 0 | G4: =F4 -> 0 | H4: =G4 -> 0
B5: QRT 01 | F5: =(C5*D5)-E5 -> 0 | G5: =F5 -> 0 | H5: =G5 -> 0
B6: QRT 02 | F6: =(C6*D6)-E6 -> 0 | G6: =F6 -> 0 | H6: =G6 -> 0
B7: QRT 03 | F7: =(C7*D7)-E7 -> 0 | G7: =F7 -> 0 | H7: =G7 -> 0
B8: CORREDOR | F8: =(C8*D8)-E8 -> 0 | G8: =F8 -> 0 | H8: =G8 -> 0
B9: QRT DEPENDENCIA | F9: =(C9*D9)-E9 -> 0 | G9: =F9 -> 0 | H9: =G9 -> 0
B10: BWC SOCIAL | F10: =(C10*D10)-E10 -> 0 | G10: =F10 -> 0 | H10: =G10 -> 0
B11: BWC SUITE 1 | F11: =(C11*D11)-E11 -> 0 | G11: =F11 -> 0 | H11: =G11 -> 0
B12: BWC SUITE 2 | F12: =(C12*D12)-E12 -> 0 | G12: =F12 -> 0 | H12: =G12 -> 0
B13: BWC SUITE 3 | F13: =(C13*D13)-E13 -> 0 | G13: =F13 -> 0 | H13: =G13 -> 0
F14: =(C14*D14)-E14 -> 0 | G14: =F14 -> 0 | H14: =G14 -> 0
F15: =(C15*D15)-E15 -> 0 | G15: =F15 -> 0 | H15: =G15 -> 0
F16: =(C16*D16)-E16 -> 0 | G16: =F16 -> 0 | H16: =G16 -> 0
F17: =(C17*D17)-E17 -> 0 | G17: =F17 -> 0 | H17: =G17 -> 0
F18: =(C18*D18)-E18 -> 0 | G18: =F18 -> 0 | H18: =G18 -> 0
F19: =(C19*D19)-E19 -> 0 | G19: =F19 -> 0 | H19: =G19 -> 0
F20: =(C20*D20)-E20 -> 0 | G20: =F20 -> 0 | H20: =G20 -> 0
F21: =(C21*D21)-E21 -> 0 | G21: =F21 -> 0 | H21: =G21 -> 0
F22: =(C22*D22)-E22 -> 0 | G22: =F22 -> 0 | H22: =G22 -> 0
F23: =(C23*D23)-E23 -> 0 | G23: =F23 -> 0 | H23: =G23 -> 0
F24: =(C24*D24)-E24 -> 0 | G24: =F24 -> 0 | H24: =G24 -> 0
B26: LEVANTAMENTO DE QUANTITATIVOS EM PISO E FORRO
D27: REVESTIMENTO | G27: PISO | I27: FORRO
B28: AMBIENTE | C28: ÁREA | D28: PORCELAN. | E28: CERÂMICA | F28: GRANITO | G28: CONTRAPISO | H28: IMPERMEAB | I28: GESSO | J28: SELADOR/MASSA | K28: PINTURA
B29: SALA | C29: 12.08 | D29: 0 | E29: 12.08 | F29: 0 | G29: 0 | H29: 0
B30: QRT 01 | C30: 7.8 | D30: 0 | E30: 7.8 | F30: 0 | G30: 0 | H30: 0
B31: QRT 02 | C31: 7.8 | D31: 0 | E31: 7.8 | F31: 0 | G31: 0 | H31: 0
B32: QRT 03 | C32: 0 | D32: 0 | E32: 0 | F32: 0 | G32: 0 | H32: 0
B33: CORREDOR | C33: 2.57 | D33: 0 | E33: 2.57 | F33: 0 | G33: 0 | H33: 0
B34: QRT DEPENDENCIA | C34: 0 | D34: 0 | E34: 0 | F34: 0 | G34: 0 | H34: 0
B35: BWC SOCIAL | C35: 0 | D35: 0 | E35: 0 | F35: 0 | G35: 0 | H35: 0
B36: BWC SUITE 1 | C36: 0 | D36: 0 | E36: 0 | F36: 0 | G36: 0 | H36: 0
B37: BWC SUITE 2 | C37: 0 | D37: 0 | E37: 0 | F37: 0 | G37: 0 | H37: 0
B38: BWC SUITE 3 | C38: 0 | D38: 0 | E38: 0 | F38: 0 | G38: 0 | H38: 0
B39: COZINHA/A. SERV | C39: 6.84 | D39: 0 | E39: 6.84 | F39: 0 | G39: 0 | H39: 0
D40: 0 | F40: 0 | G40: 0 | H40: 0
B41: TOTAL | C41: =SUM(C29:C39) -> 37.09 | D41: 0 | F41: 0 | G41: 0 | H41: 0
...

Sheet 3. CPU
A1: CLIENTE: | B1: ='1. BRIEFING'!B2 -> - | G1: FUNÇÃO | H1: R$ HORA | I1: FUNÇÃO | J1: R$ HORA
A2: ARQ.: | B2: ='1. BRIEFING'!B3 -> - | E2: CUSTO MO | F2: 0 | G2: PEDREIRO | H2: 25.38 | I2: GESSEIRO | J2: 25.18
A3: OBRA: | B3: ='1. BRIEFING'!B4 -> - | E3: CUSTO MAT | F3: 0 | G3: SERVENTE | H3: 20.42 | I3: ELETRICISTA | J3: 25.69
B4: ='1. BRIEFING'!B5 -> 0 | E4: CUSTO SERV | F4: 0 | G4: ENCANDOR | H4: 24.63 | I4: AZULEJISTA | J4: 25.25
E5: CUSTO TOTAL | F5: 0 | G5: AUX. ENCANADOR | H5: 19.82
A6: COMPOSIÇÃO DE PREÇO UNITÁRIO PROPRIA
A7: ITEM | B7: DESCRIÇÃO DOS SERVIÇOS | C7: UND | D7: QNTD | E7: R$ UNIT | F7: R$ TOTAL | G7: COEFIC. | H7: R$ HORA
A8: ='1. BRIEFING'!A14 -> 2 | B8: ='1. BRIEFING'!B14 -> DEMOLIÇÃO E RETIRADA
A9: ='1. BRIEFING'!A15 -> 2.1 | B9: ='1. BRIEFING'!B15 -> DEMOLIÇÃO DE ALVENARIA DE VEDAÇÃO | C9: M2 | D9: ='1. BRIEFING'!D15 -> 1,00 | E9: =F9/D9 -> 62.5 | F9: =SUM(F10:F12) -> 62.5 | G9: COEF. | H9: R$ HORA
A10: MAT | B10: SACOS PARA ENTULHO | C10: UN | D10: 1 | E10: 2.5 | F10: =(E10*D10)*$D$9 -> 2.5
A11: MO | B11: PEDREIRO l DEMOLIÇÃO DE ALVENARIA | C11: M2 | D11: 1 | E11: 30 | F11: =(E11*D11)*$D$9 -> 30 | G11: 0.255 | H11: =H2 -> 25.38
A12: MO | B12: SERVENTE l DEMOLIÇÃO DE ALVENARIA | C12: M2 | D12: 1 | E12: 30 | F12: =(E12*D12)*$D$9 -> 30 | G12: 2.325 | H12: =H3 -> 20.42
C13: MO | D13: =F12/D9 -> 30 | E13: MAT | F13: =F10/D9 -> 2.5
A14: ='1. BRIEFING'!A16 -> 2.2 | B14: ='1. BRIEFING'!B16 -> REMOÇÃO DE BANCADAS EM GRANITO | C14: UN | D14: ='1. BRIEFING'!D16 -> 1,00 | E14: =F14/D14 -> 50 | F14: =SUM(F15) -> 50 | G14: COEF. | H14: R$ HORA
A15: MO | B15: SERVENTE l REMOÇÃO DE BANCADA EM GRANITO | C15: UN | D15: 1 | E15: 50 | F15: =(E15*D15)*D14 -> 50 | G15: 0.2 | H15: =H3 -> 20.42
C16: MO | D16: =F15/D14 -> 50 | E16: MAT | F16: 0
A17: ='1. BRIEFING'!A17 -> 2.3 | B17: ='1. BRIEFING'!B17 -> REMOÇÃO DE LOUÇAS E METAIS | C17: UN | D17: ='1. BRIEFING'!D17 -> 1,00 | E17: =F17/D17 -> 1027 | F17: =SUM(F18:F20) -> 1027 | G17: COEF. | H17: R$ HORA
A18: MO | B18: ENCANADOR l REMOÇÃO DE LOUÇAS E METAIS | C18: UN | D18: 1 | E18: 20 | F18: =(E18*D18)*D16 -> 1000 | G18: 0.1755 | H18: =H4 -> 24.63
A19: MO | B19: SERVENTE l REMOÇÃO DE LOUÇAS E METAIS | C19: UN | D19: 1 | E19: 25 | F19: =(E19*D19)*D17 -> 25 | G19: 0.3448 | H19: =H3 -> 20.42
A20: MAT | B20: SACOS PARA ENTULHO | C20: UN | D20: 1 | E20: 2 | F20: =(E20*D20)*D17 -> 2
C21: MO | D21: =SUM(F18:F19)/D17 -> 1025 | E21: MAT | F21: =F20/D17 -> 2
A22: ='1. BRIEFING'!A18 -> 2.4 | B22: ='1. BRIEFING'!B18 -> REMOÇÃO DE PORTAS INTERNAS EM MADEIRA | C22: UN | D22: ='1. BRIEFING'!D18 -> 1,00 | E22: =F22/D22 -> 70 | F22: =SUM(F23:F24) -> 70 | G22: COEF. | H22: R$ HORA
A23: MO | B23: PEDREIRO l REMOÇÃO DE PORTA EM MADEIRA | C23: UN | D23: 1 | E23: 50 | F23: =(E23*D23)*D22 -> 50 | G23: 0.1315 | H23: =H2 -> 25.38
A24: MO | B24: SERVENTE l REMOÇÃO DE PORTA EM MADEIRA | C24: UN | D24: 1 | E24: 20 | F24: =(E24*D24)*D22 -> 20 | G24: 0.2582 | H24: =H3 -> 20.42
C25: MO | D25: =F24/D22 -> 20 | E25: MAT | F25: 0
A26: ='1. BRIEFING'!A19 -> 2.5 | B26: ='1. BRIEFING'!B19 -> DEMOLIÇÃO DE REVESTIMENTO CERÂMICO EM PAREDE | C26: M2 | D26: ='1. BRIEFING'!D19 -> 1,00 | E26: =F26/D26 -> 12.5 | F26: =SUM(F28:F29) -> 12.5 | G26: COEF. | H26: R$ HORA
A27: MO | B27: AZULEJISTA l DEMOLIÇÃO DE REVESTIMENTO CERÂMICO EM PAREDE | C27: M² | D27: 1 | E27: 20 | F27: =(E27*D27)*$D$26 -> 20 | G27: 0.2553 | H27: =J4 -> 25.25
A28: MO | B28: SERVENTE l DEMOLIÇÃO DE REVESTIMENTO CERÂMICO EM PAREDE | C28: M² | D28: 1 | E28: 10 | F28: =(E28*D28)*$D$26 -> 10 | G28: 0.7195 | H28: =H3 -> 20.42
A29: MAT | B29: SACOS PARA ENTULHO | C29: UN | D29: 1 | E29: 2.5 | F29: =(E29*D29)*$D$26 -> 2.5
C30: MO | D30: =F28/D26 -> 10 | E30: MAT | F30: =(F28+F29)/D26 -> 12.5
A31: ='1. BRIEFING'!A20 -> 2.6 | B31: ='1. BRIEFING'!B20 -> DEMOLIÇÃO DE REVESTIMENTO CERÂMICO EM PISO | C31: M2 | D31: ='1. BRIEFING'!D20 -> 1,00 | E31: =F31/D31 -> 27.5 | F31: =SUM(F33:F34) -> 27.5 | G31: COEF. | H31: R$ HORA
A32: MO | B32: AZULEJISTA l DEMOLIÇÃO DE REVESTIMENTO CERÂMICO EM PISO | C32: M² | D32: 1 | E32: 20 | F32: =(E32*D32)*$D$26 -> 20 | G32: 0.2553 | H32: =J4 -> 25.25
A33: MO | B33: SERVENTE l DEMOLIÇÃO DE REVESTIMENTO CERÂMICO EM PISO | C33: M² | D33: 1 | E33: 25 | F33: =(E33*D33)*$D$31 -> 25 | G33: 0.7195 | H33: =H3 -> 20.42
A34: MAT | B34: SACOS PARA ENTULHO | C34: UN | D34: 1 | E34: 2.5 | F34: =(E34*D34)*$D$31 -> 2.5
C35: MO | D35: =F33/D31 -> 25 | E35: MAT | F35: =F34/D31 -> 2.5
A36: ='1. BRIEFING'!A21 -> 2.7 | B36: ='1. BRIEFING'!B21 -> DEMOLIÇÃO DE FORRO EM GESSO/PVC | C36: M2 | D36: ='1. BRIEFING'!D21 -> 1,00 | E36: =F36/D36 -> 9.5 | F36: =SUM(F38:F39) -> 9.5 | G36: COEF. | H36: R$ HORA
A37: MO | B37: GESSEIRO l DEMOLIÇÃO DE FORRO EM GESSO/PVC | C37: M² | D37: 1 | E37: 5 | F37: =(E37*D37)*$D$36 -> 5 | G37: 0.0713 | H37: =J2 -> 25.18
A38: MO | B38: SERVENTE l DEMOLIÇÃO DE FORRO EM GESSO/PVC | C38: M² | D38: 1 | E38: 7 | F38: =(E38*D38)*$D$36 -> 7 | G38: 0.1401 | H38: =H3 -> 20.42
A39: MAT | B39: SACO PARA ENTULHO | C39: UN | D39: 1 | E39: 2.5 | F39: =(E39*D39)*$D$36 -> 2.5
C40: MO | D40: =F38/D36 -> 7 | E40: MAT | F40: =F39/D36 -> 2.5
...

Sheet 4. PLAN ORÇA
A1: CLIENTE: | L1: SUA LOGO AQUI!
A2: ARQ.:
A3: OBRA:
A4: PLANILHA ORÇAMENTÁRIA l MÃO DE OBRA l MATERIAL l SERVIÇO
A6: ITEM | B6: DESCRIÇÃO DOS SERVIÇOS | C6: UND | D6: QNTD | E6: R$ UNIT | F6: VALOR UNITÁRIO
F7: M.O | G7: MAT | H7: SERVIÇO | I7: TOTAL UNIT | J7: M.O | K7: MAT | L7: SERVIÇO | M7: TOTAL | N7: PREÇO TOTAL
A8: ='1. BRIEFING'!A8 -> 1 | B8: ='1. BRIEFING'!B8 -> SERVIÇOS ADIMINSTRATIVOS | C8: ='1. BRIEFING'!C8 -> 0 | J8: =SUM(J9:J13) -> 0 | K8: =SUM(K9:K13) -> 0 | L8: =SUM(L9:L13) -> 0 | M8: =SUM(M9:M13) -> 0 | N8: =SUM(N9:N13) -> 0 | O8: =N8/$N$92 -> 0
A9: ='1. BRIEFING'!A9 -> 1.1 | B9: ='1. BRIEFING'!B9 -> ADMINISTRAÇÃO DE OBRA | C9: ='1. BRIEFING'!C9 -> MES | D9: ='1. BRIEFING'!D9 -> 1 | E9: =I9 -> 0 | F9: 0 | G9: 0 | H9: 0 | I9: =SUM(F9:H9) -> 0 | J9: =F9*D9 -> 0 | K9: =G9*D9 -> 0 | L9: =H9*D9 -> 0 | M9: =SUM(J9:L9) -> 0 | N9: =M9*(1+$N$96) -> 0
A10: ='1. BRIEFING'!A10 -> 1.2 | B10: ='1. BRIEFING'!B10 -> TRANSPORTE E ALIMENTAÇÃO EQP ADM | C10: ='1. BRIEFING'!C10 -> MES | D10: ='1. BRIEFING'!D10 -> 1 | E10: =I10 -> 0 | F10: 0 | G10: 0 | H10: 0 | I10: =SUM(F10:H10) -> 0 | J10: =F10*D10 -> 0 | K10: =G10*D10 -> 0 | L10: =H10*D10 -> 0 | M10: =SUM(J10:L10) -> 0 | N10: =M10*(1+$N$96) -> 0
A11: ='1. BRIEFING'!A11 -> 1.3 | B11: ='1. BRIEFING'!B11 -> ART DE EXECUÇÃO DA OBRA | C11: ='1. BRIEFING'!C11 -> UN | D11: ='1. BRIEFING'!D11 -> 1 | E11: =I11 -> 0 | F11: 0 | G11: 0 | H11: 0 | I11: =SUM(F11:H11) -> 0 | J11: =F11*D11 -> 0 | K11: =G11*D11 -> 0 | L11: =H11*D11 -> 0 | M11: =SUM(J11:L11) -> 0 | N11: =M11*(1+$N$96) -> 0
A12: ='1. BRIEFING'!A12 -> 1.4 | B12: ='1. BRIEFING'!B12 -> ISOLAMENTO/PROTEÇÃO COM LONA/PLÁSTICO BOLHA | C12: ='1. BRIEFING'!C12 -> VB | D12: ='1. BRIEFING'!D12 -> 1 | E12: =I12 -> 0 | F12: 0 | G12: 0 | H12: 0 | I12: =SUM(F12:H12) -> 0 | J12: =F12*D12 -> 0 | K12: =G12*D12 -> 0 | L12: =H12*D12 -> 0 | M12: =SUM(J12:L12) -> 0 | N12: =M12*(1+$N$96) -> 0
A13: ='1. BRIEFING'!A13 -> 1.5 | B13: ='1. BRIEFING'!B13 -> MOBILIZAÇÃO E DESMOBILIZAÇÃO | C13: ='1. BRIEFING'!C13 -> UN | D13: ='1. BRIEFING'!D13 -> 1 | E13: =I13 -> 0 | F13: 0 | G13: 0 | H13: 0 | I13: =SUM(F13:H13) -> 0 | J13: =F13*D13 -> 0 | K13: =G13*D13 -> 0 | L13: =H13*D13 -> 0 | M13: =SUM(J13:L13) -> 0 | N13: =M13*(1+$N$96) -> 0
A14: ='1. BRIEFING'!A14 -> 2 | B14: ='1. BRIEFING'!B14 -> DEMOLIÇÃO E RETIRADA | J14: =SUM(J15:J23) -> 800 | K14: =SUM(K15:K23) -> 7 | L14: =SUM(L15:L23) -> 400 | M14: =SUM(M15:M23) -> 1207 | N14: =SUM(N15:N23) -> 1609.3333 | O14: =N14/$N$92 -> 0.041793281
A15: ='1. BRIEFING'!A15 -> 2.1 | B15: ='1. BRIEFING'!B15 -> DEMOLIÇÃO DE ALVENARIA DE VEDAÇÃO | C15: ='1. BRIEFING'!C15 -> M² | D15: ='1. BRIEFING'!D15 -> 1,00 | E15: =I15 -> 32.5 | F15: ='3. CPU'!E12 -> 30 | G15: ='3. CPU'!E10 -> 2.5 | H15: 0 | I15: =SUM(F15:H15) -> 32.5 | J15: =F15*D15 -> 30 | K15: =G15*D15 -> 2.5 | L15: =H15*D15 -> 0 | M15: =SUM(J15:L15) -> 32.5 | N15: =M15*(1+$N$96) -> 43.333333
A16: ='1. BRIEFING'!A16 -> 2.2 | B16: ='1. BRIEFING'!B16 -> REMOÇÃO DE BANCADAS EM GRANITO | C16: ='1. BRIEFING'!C16 -> UND | D16: ='1. BRIEFING'!D16 -> 1,00 | E16: =I16 -> 150 | F16: 150 | G16: 0 | H16: 0 | I16: =SUM(F16:H16) -> 150 | J16: =F16*D16 -> 150 | K16: =G16*D16 -> 0 | L16: =H16*D16 -> 0 | M16: =SUM(J16:L16) -> 150 | N16: =M16*(1+$N$96) -> 200
A17: ='1. BRIEFING'!A17 -> 2.3 | B17: ='1. BRIEFING'!B17 -> REMOÇÃO DE LOUÇAS E METAIS | C17: ='1. BRIEFING'!C17 -> VB | D17: ='1. BRIEFING'!D17 -> 1,00 | E17: =I17 -> 350 | F17: 350 | G17: 0 | H17: 0 | I17: =SUM(F17:H17) -> 350 | J17: =F17*D17 -> 350 | K17: =G17*D17 -> 0 | L17: =H17*D17 -> 0 | M17: =SUM(J17:L17) -> 350 | N17: =M17*(1+$N$96) -> 466.66667
A18: ='1. BRIEFING'!A18 -> 2.4 | B18: ='1. BRIEFING'!B18 -> REMOÇÃO DE PORTAS INTERNAS EM MADEIRA | C18: ='1. BRIEFING'!C18 -> UN | D18: ='1. BRIEFING'!D18 -> 1,00 | E18: =I18 -> 75 | F18: 75 | G18: 0 | H18: 0 | I18: =SUM(F18:H18) -> 75 | J18: =F18*D18 -> 75 | K18: =G18*D18 -> 0 | L18: =H18*D18 -> 0 | M18: =SUM(J18:L18) -> 75 | N18: =M18*(1+$N$96) -> 100
A19: ='1. BRIEFING'!A19 -> 2.5 | B19: ='1. BRIEFING'!B19 -> DEMOLIÇÃO DE REVESTIMENTO CERÂMICO EM PAREDE | C19: ='1. BRIEFING'!C19 -> M² | D19: ='1. BRIEFING'!D19 -> 1,00 | E19: =I19 -> 26.5 | F19: 25 | G19: 1.5 | H19: 0 | I19: =SUM(F19:H19) -> 26.5 | J19: =F19*D19 -> 25 | K19: =G19*D19 -> 1.5 | L19: =H19*D19 -> 0 | M19: =SUM(J19:L19) -> 26.5 | N19: =M19*(1+$N$96) -> 35.333333
A20: ='1. BRIEFING'!A20 -> 2.6 | B20: ='1. BRIEFING'!B20 -> DEMOLIÇÃO DE REVESTIMENTO CERÂMICO EM PISO | C20: ='1. BRIEFING'!C20 -> M² | D20: ='1. BRIEFING'!D20 -> 1,00 | E20: =I20 -> 26.5 | F20: 25 | G20: 1.5 | H20: 0 | I20: =SUM(F20:H20) -> 26.5 | J20: =F20*D20 -> 25 | K20: =G20*D20 -> 1.5 | L20: =H20*D20 -> 0 | M20: =SUM(J20:L20) -> 26.5 | N20: =M20*(1+$N$96) -> 35.333333
A21: ='1. BRIEFING'!A21 -> 2.7 | B21: ='1. BRIEFING'!B21 -> DEMOLIÇÃO DE FORRO EM GESSO/PVC | C21: ='1. BRIEFING'!C21 -> M² | D21: ='1. BRIEFING'!D21 -> 1,00 | E21: =I21 -> 11.5 | F21: 10 | G21: 1.5 | H21: 0 | I21: =SUM(F21:H21) -> 11.5 | J21: =F21*D21 -> 10 | K21: =G21*D21 -> 1.5 | L21: =H21*D21 -> 0 | M21: =SUM(J21:L21) -> 11.5 | N21: =M21*(1+$N$96) -> 15.333333
A22: ='1. BRIEFING'!A22 -> 2.8 | B22: ='1. BRIEFING'!B22 -> REMOÇÃO DE LUMINÁRIAS INTERNAS (FORRO) | C22: ='1. BRIEFING'!C22 -> UN | D22: ='1. BRIEFING'!D22 -> 1,00 | E22: =I22 -> 15 | F22: 15 | G22: 0 | H22: 0 | I22: =SUM(F22:H22) -> 15 | J22: =F22*D22 -> 15 | K22: =G22*D22 -> 0 | L22: =H22*D22 -> 0 | M22: =SUM(J22:L22) -> 15 | N22: =M22*(1+$N$96) -> 20
A23: ='1. BRIEFING'!A23 -> 2.9 | B23: ='1. BRIEFING'!B23 -> REMOÇÃO DOS ENTULHOS POR SACOS E CARRO PEQUENO | C23: ='1. BRIEFING'!C23 -> UN | D23: ='1. BRIEFING'!D23 -> 1,00 | E23: =I23 -> 520 | F23: 120 | G23: 0 | H23: 400 | I23: =SUM(F23:H23) -> 520 | J23: =F23*D23 -> 120 | K23: =G23*D23 -> 0 | L23: =H23*D23 -> 400 | M23: =SUM(J23:L23) -> 520 | N23: =M23*(1+$N$96) -> 693.33333
A24: ='1. BRIEFING'!A24 -> 3 | B24: ='1. BRIEFING'!B24 -> SERVIÇO EM ALVENARIA | J24: =SUM(J25) -> 30 | K24: =SUM(K25) -> 40.28 | L24: =SUM(L25) -> 0 | M24: =SUM(M25) -> 70.28 | N24: =SUM(N25) -> 93.706667 | O24: =N24/$N$92 -> 0.0024334978
A25: ='1. BRIEFING'!A25 -> 3.1 | B25: ='1. BRIEFING'!B25 -> ASSENTAMENTO DE ALVENARIA DE VEDAÇÃO | C25: ='1. BRIEFING'!C25 -> M² | D25: ='1. BRIEFING'!D25 -> 1 | E25: =I25 -> 70.28 | F25: 30 | G25: 40.28 | H25: 0 | I25: =SUM(F25:H25) -> 70.28 | J25: =F25*D25 -> 30 | K25: =G25*D25 -> 40.28 | L25: =H25*D25 -> 0 | M25: =SUM(J25:L25) -> 70.28 | N25: =M25*(1+$N$96) -> 93.706667
A26: ='1. BRIEFING'!A29 -> 4 | B26: ='1. BRIEFING'!B29 -> INSTALAÇÃO HIDRÁULICA | J26: =SUM(J27:J31) -> 530 | K26: =SUM(K27:K31) -> 274.33 | L26: =SUM(L27:L31) -> 0 | M26: =SUM(M27:M31) -> 804.33 | N26: =SUM(N27:N31) -> 1072.44 | O26: =N26/$N$92 -> 0.02785053
A27: ='1. BRIEFING'!A30 -> 4.1 | B27: ='1. BRIEFING'!B30 -> INSTALAÇAO DE PONTO DE ÁGUA FRIA | C27: ='1. BRIEFING'!C30 -> UN | D27: ='1. BRIEFING'!D30 -> 10 | E27: =I27 -> 48.5 | F27: 40 | G27: 8.5 | H27: 0 | I27: =SUM(F27:H27) -> 48.5 | J27: =F27*D27 -> 400 | K27: =G27*D27 -> 85 | L27: =H27*D27 -> 0 | M27: =SUM(J27:L27) -> 485 | N27: =M27*(1+$N$96) -> 646.66667
A28: ='1. BRIEFING'!A31 -> 4.2 | B28: ='1. BRIEFING'!B31 -> INSTALAÇÃO DE PONTO DE ESGOTO 50 MM | C28: ='1. BRIEFING'!C31 -> UN | D28: ='1. BRIEFING'!D31 -> 1 | E28: =I28 -> 104.19 | F28: 30 | G28: 74.19 | H28: 0 | I28: =SUM(F28:H28) -> 104.19 | J28: =F28*D28 -> 30 | K28: =G28*D28 -> 74.19 | L28: =H28*D28 -> 0 | M28: =SUM(J28:L28) -> 104.19 | N28: =M28*(1+$N$96) -> 138.92
A29: ='1. BRIEFING'!A32 -> 4.3 | B29: ='1. BRIEFING'!B32 -> RELOCAÇÃO DE PONTO DE ESGOTO 100 MM | C29: ='1. BRIEFING'!C32 -> UN | D29: ='1. BRIEFING'!D32 -> 1 | E29: =I29 -> 50.7 | F29: 30 | G29: 20.7 | H29: 0 | I29: =SUM(F29:H29) -> 50.7 | J29: =F29*D29 -> 30 | K29: =G29*D29 -> 20.7 | L29: =H29*D29 -> 0 | M29: =SUM(J29:L29) -> 50.7 | N29: =M29*(1+$N$96) -> 67.6
A30: ='1. BRIEFING'!A33 -> 4.4 | B30: ='1. BRIEFING'!B33 -> INSTALAÇÃO DE PONTO DE REGISTRO DE GAVETA | C30: ='1. BRIEFING'!C33 -> UN | D30: ='1. BRIEFING'!D33 -> 1 | E30: =I30 -> 82.22 | F30: 35 | G30: 47.22 | H30: 0 | I30: =SUM(F30:H30) -> 82.22 | J30: =F30*D30 -> 35 | K30: =G30*D30 -> 47.22 | L30: =H30*D30 -> 0 | M30: =SUM(J30:L30) -> 82.22 | N30: =M30*(1+$N$96) -> 109.62667
A31: ='1. BRIEFING'!A34 -> 4.5 | B31: ='1. BRIEFING'!B34 -> INSTALAÇÃO DE PONTO DE REGISTRO DE PRESSÃO | C31: ='1. BRIEFING'!C34 -> UN | D31: ='1. BRIEFING'!D34 -> 1 | E31: =I31 -> 82.22 | F31: 35 | G31: 47.22 | H31: 0 | I31: =SUM(F31:H31) -> 82.22 | J31: =F31*D31 -> 35 | K31: =G31*D31 -> 47.22 | L31: =H31*D31 -> 0 | M31: =SUM(J31:L31) -> 82.22 | N31: =M31*(1+$N$96) -> 109.62667
A32: ='1. BRIEFING'!A35 -> 5 | B32: ='1. BRIEFING'!B35 -> INSTALAÇÃO ELÉTRICA | J32: =SUM(J33:J37) -> 175 | K32: =SUM(K33:K37) -> 0 | L32: =SUM(L33:L37) -> 0 | M32: =SUM(M33:M37) -> 175 | N32: =SUM(N33:N37) -> 233.33333 | O32: =N32/$N$92 -> 0.0060595064
A33: ='1. BRIEFING'!A36 -> 5.1 | B33: ='1. BRIEFING'!B36 -> INSTALAÇÃO DE INFRAESTRUTURA PARA TOMADA E ILUMINAÇÃO | C33: ='1. BRIEFING'!C36 -> UN | D33: ='1. BRIEFING'!D36 -> 1 | E33: =I33 -> 35 | F33: 35 | G33: 0 | H33: 0 | I33: =SUM(F33:H33) -> 35 | J33: =F33*D33 -> 35 | K33: =G33*D33 -> 0 | L33: =H33*D33 -> 0 | M33: =SUM(J33:L33) -> 35 | N33: =M33*(1+$N$96) -> 46.666667
A34: ='1. BRIEFING'!A37 -> 5.2 | B34: ='1. BRIEFING'!B37 -> INSTALAÇÃO DE CABEAMENTO PARA PONTOS DE TOMADAS | C34: ='1. BRIEFING'!C37 -> UN | D34: ='1. BRIEFING'!D37 -> 1 | E34: =I34 -> 35 | F34: 35 | G34: 0 | H34: 0 | I34: =SUM(F34:H34) -> 35 | J34: =F34*D34 -> 35 | K34: =G34*D34 -> 0 | L34: =H34*D34 -> 0 | M34: =SUM(J34:L34) -> 35 | N34: =M34*(1+$N$96) -> 46.666667
A35: ='1. BRIEFING'!A38 -> 5.3 | B35: ='1. BRIEFING'!B38 -> INSTALAÇÃO DE CABEAMENTO PARA PONTOS DE ILUMINAÇÃO | C35: ='1. BRIEFING'!C38 -> UN | D35: ='1. BRIEFING'!D38 -> 1 | E35: =I35 -> 35 | F35: 35 | G35: 0 | H35: 0 | I35: =SUM(F35:H35) -> 35 | J35: =F35*D35 -> 35 | K35: =G35*D35 -> 0 | L35: =H35*D35 -> 0 | M35: =SUM(J35:L35) -> 35 | N35: =M35*(1+$N$96) -> 46.666667
A36: ='1. BRIEFING'!A39 -> 5.4 | B36: ='1. BRIEFING'!B39 -> REISNTALAÇÃO DE QUADRO DE DISTRIBUIÇÃO (ADEQUAÇÃO) | C36: ='1. BRIEFING'!C39 -> VB | D36: ='1. BRIEFING'!D39 -> 1 | E36: =I36 -> 35 | F36: 35 | G36: 0 | H36: 0 | I36: =SUM(F36:H36) -> 35 | J36: =F36*D36 -> 35 | K36: =G36*D36 -> 0 | L36: =H36*D36 -> 0 | M36: =SUM(J36:L36) -> 35 | N36: =M36*(1+$N$96) -> 46.666667
A37: ='1. BRIEFING'!A40 -> 5.5 | B37: ='1. BRIEFING'!B40 -> INSTALAÇÃO DE INFRAESTRUTURA PARA PONTOS DE REDE/ANTENA/CAMERA/SOM | C37: ='1. BRIEFING'!C40 -> UN | D37: ='1. BRIEFING'!D40 -> 1 | E37: =I37 -> 35 | F37: 35 | G37: 0 | H37: 0 | I37: =SUM(F37:H37) -> 35 | J37: =F37*D37 -> 35 | K37: =G37*D37 -> 0 | L37: =H37*D37 -> 0 | M37: =SUM(J37:L37) -> 35 | N37: =M37*(1+$N$96) -> 46.666667
A38: ='1. BRIEFING'!A41 -> 6 | B38: ='1. BRIEFING'!B41 -> INSTALAÇÃO DE EQUIPAMENTOS | J38: =SUM(J39:J41) -> 250 | K38: =SUM(K39:K41) -> 125.63 | L38: =SUM(L39:L41) -> 0 | M38: =SUM(M39:M41) -> 375.63 | N38: =SUM(N39:N41) -> 500.84 | O38: =N38/$N$92 -> 0.013006471
A39: ='1. BRIEFING'!A42 -> 6.1 | B39: ='1. BRIEFING'!B42 -> INSTALAÇÃO DE INFRA PARA AR CONDICIONADO | C39: ='1. BRIEFING'!C42 -> UN | D39: ='1. BRIEFING'!D42 -> 1 | E39: =I39 -> 94.43 | F39: 50 | G39: 44.43 | H39: 0 | I39: =SUM(F39:H39) -> 94.43 | J39: =F39*D39 -> 50 | K39: =G39*D39 -> 44.43 | L39: =H39*D39 -> 0 | M39: =SUM(J39:L39) -> 94.43 | N39: =M39*(1+$N$96) -> 125.90667
A40: ='1. BRIEFING'!A43 -> 6.2 | B40: ='1. BRIEFING'!B43 -> INSTALAÇÃO DE BOILER | C40: ='1. BRIEFING'!C43 -> UN | D40: ='1. BRIEFING'!D43 -> 1 | E40: =I40 -> 131.2 | F40: 50 | G40: 81.2 | H40: 0 | I40: =SUM(F40:H40) -> 131.2 | J40: =F40*D40 -> 50 | K40: =G40*D40 -> 81.2 | L40: =H40*D40 -> 0 | M40: =SUM(J40:L40) -> 131.2 | N40: =M40*(1+$N$96) -> 174.93333
A41: ='1. BRIEFING'!A44 -> 6.3 | B41: ='1. BRIEFING'!B44 -> INSTALAÇÃO DE EXAUSTOR l BWC CAMARIM E MAS | C41: ='1. BRIEFING'!C44 -> UN | D41: ='1. BRIEFING'!D44 -> 1 | E41: =I41 -> 150 | F41: 150 | G41: 0 | H41: 0 | I41: =SUM(F41:H41) -> 150 | J41: =F41*D41 -> 150 | K41: =G41*D41 -> 0 | L41: =H41*D41 -> 0 | M41: =SUM(J41:L41) -> 150 | N41: =M41*(1+$N$96) -> 200
...

Sheet 4. CUSTO IND
G1: Normalmente varia de 5% a 30% do custo total da obra
B2: EQUIPE TÉCNICA | G2: CUSTO INDIRETO | H2: =SUM(H3:H9,J3:J9) -> 0
B3: CARGOS | C3: QNTD | D3: SALÁRIO | E3: TOTAL | G3: EQUIPE TECNICA | H3: =E9 -> 0 | I3: EQP EPI | J3: =E91+J91 -> 0 | L3: O QUE INCLUI?
B4: ENGENHEIRO CIVIL (MÊS) | C4: 0 | D4: 0 | E4: =D4*C4 -> 0 | G4: EQUIPE DE SUPORTE | H4: =E20+J20 -> 0 | I4: FERRAMENTA | J4: =E116+J116 -> 0 | L4: CUSTOS ACRESCIDOS DOS ENCARGOS SOCIAIS E TRABALHISTAS (MENSALISTA)
B5: ENGENHEIRO CIVIL (VISITA) | C5: 0 | D5: 0 | E5: =D5*C5 -> 0 | G5: EQUIPE ADMINISTRATIVA | H5: =E29+J29 -> 0 | I5: DESP CORRENTE | J5: =E131 -> 0
B6: ENCARREGADO DE OBRAS | C6: 0 | D6: 0 | E6: =D6*C6 -> 0 | G6: MOBILIZAÇÃO E DESMOBILIZAÇÃO | H6: =E41 -> 0 | I6: DESP PESSOAL | J6: =E143 -> 0
B7: ENCARREGADO (SEMANA) | C7: 0 | D7: 0 | E7: =D7*C7 -> 0 | G7: EQP CANTEIRO | H7: =E59+J59 -> 0 | I7: SERV TERCEIRO | J7: =E153 -> 0
B8: ESTÁGIARIO/MÊS (BOLSA+PASSAG+REFEIÇÃO) | C8: 0 | D8: 0 | E8: =D8*C8 -> 0 | G8: EQP ADMINISTRATIVA | H8: =E73+J73 -> 0 | I8: TAXAS E EMOLU | J8: =E163 -> 0
D9: TOTAL EQP TÉCNICA | E9: =SUM(E4:E8) -> 0 | G9: EQP PROT. COLETIVA | H9: =E81 -> 0 | I9: DIVERSOS | J9: =E180 -> 0
B11: EQUIPE DE SUPORTE
B12: FUNÇÕES | C12: QNTD | D12: SALÁRIO | E12: TOTAL | G12: FUNÇÕES | H12: QNTD | I12: SALÁRIO | J12: TOTAL | L12: O QUE INCLUI?
B13: ALMOXARIFE | C13: 0 | D13: 0 | E13: =D13*C13 -> 0 | G13: TOPÓGRAFO | H13: 0 | I13: 0 | J13: =I13*H13 -> 0 | L13: CUSTOS ACRESCIDOS DOS ENCARGOS SOCIAIS E TRABALHISTAS (MENSALISTA)
B14: FERRAMENTEIRO | C14: 0 | D14: 0 | E14: =D14*C14 -> 0 | G14: AUXILIAR TOPOGAFIA (Hr) | H14: 0 | I14: 0 | J14: =I14*H14 -> 0
B15: APONTADOR | C15: 0 | D15: 0 | E15: =D15*C15 -> 0 | G15: OPERADORES DE EQP GERAIS | H15: 0 | I15: 0 | J15: =I15*H15 -> 0
B16: COMPRADOR | C16: 0 | D16: 0 | E16: =D16*C16 -> 0 | G16: MÉDICO | H16: 0 | I16: 0 | J16: =I16*H16 -> 0
B17: AUX. LABORATORISTA (Hr) | C17: 0 | D17: 0 | E17: =D17*C17 -> 0 | G17: ENFERMEIRO | H17: 0 | I17: 0 | J17: =I17*H17 -> 0
B18: AUX. SERVIÇOS GERAIS (ELE, ENCAN, SERV) Hr | C18: 0 | D18: 0 | E18: =D18*C18 -> 0 | G18: COZINHEIRO | H18: 0 | I18: 0 | J18: =I18*H18 -> 0
B19: ASSISTENCIA SOCIAL | C19: 0 | D19: 0 | E19: =D19*C19 -> 0 | G19: AUXILIAR DE COZINHA | H19: 0 | I19: 0 | J19: =I19*H19 -> 0
D20: TOTAL EQP | E20: =SUM(E13:E19) -> 0 | I20: TOTAL EQP | J20: =SUM(J13:J19) -> 0
B22: EQUIPE ADMINISTRATIVA
B23: FUNÇÕES | C23: QNTD | D23: SALÁRIO | E23: TOTAL | G23: FUNÇÕES | H23: QNTD | I23: SALÁRIO | J23: TOTAL
B24: CHEFE DE ESCRITORIO | C24: 0 | D24: 0 | E24: =D24*C24 -> 0 | G24: PORTEIRO | H24: 0 | I24: 0 | J24: =I24*H24 -> 0
B25: AUXILIAR ADMINISTRATIVO | C25: 0 | D25: 0 | E25: =D25*C25 -> 0 | G25: VIGIA NOTURNO | H25: 0 | I25: 0 | J25: =I25*H25 -> 0
B26: SECRETÁRIA | C26: 0 | D26: 0 | E26: =D26*C26 -> 0 | G26: - | H26: 0 | I26: 0 | J26: =I26*H26 -> 0
B27: FINANCEIRO | C27: 0 | D27: 0 | E27: =D27*C27 -> 0 | G27: - | H27: 0 | I27: 0 | J27: =I27*H27 -> 0
B28: FAXINEIRA | C28: 0 | D28: 0 | E28: =D28*C28 -> 0 | G28: - | H28: 0 | I28: 0 | J28: =I28*H28 -> 0
D29: TOTAL EQP | E29: =SUM(E24:E28) -> 0 | I29: TOTAL EQP | J29: =SUM(J24:J28) -> 0
B31: MOBILIZAÇÃO E DESMOBILIZAÇÃO
B32: DESCRIÇÃO | C32: QNTD | D32: R$ VALOR | E32: R$ TOTAL | G32: O QUE INCLUI?
B33: MOBILIZAÇÃO E DESMOBILIZAÇÃO DO CANTEIRO | C33: 0 | D33: 0 | E33: =D33*C33 -> 0 | G33: MONTAGEM E DESMONTAGEM DE CONSTRUÇÕES PROVISORIAS
B34: MOBILIZAÇÃO E DESMOBILIZAÇÃO DE PESSOAL (TRANSPORTES) | C34: 0 | D34: 0 | E34: =D34*C34 -> 0 | G34: CUSTO DE DESLOCAMENTO (PASSAGEM, TRANSPORTE) E ALOJAMENTO PROVISORIO
B35: MOBILIZAÇÃO E DESMOBILIZAÇÃO DE EQUIPAMENTOS | C35: 0 | D35: 0 | E35: =D35*C35 -> 0 | G35: TRANSPORTE EM CARRETAS, MONTAGEM DE GRUA
B36: ALUGUEL DE IMOVIES PARA ESCRITÓRIO, DEPÓSITO, CONTAINES, ETC. (Mês) | C36: 0 | D36: 0 | E36: =D36*C36 -> 0 | G36: CUSTO DE LOCAÇÃO
B37: TAPUMES E CERCAS | C37: 0 | D37: 0 | E37: =D37*C37 -> 0 | G37: CONSTRUÇÃO E REMOÇÃO AO FINAL DA OBRA
B38: ILUMINAÇÃO DE CAMPOS | C38: 0 | D38: 0 | E38: =D38*C38 -> 0 | G38: MONTAGEM E REMOÇÃO DAS ESTRUTURAS
B39: LIGAÇÕES PROVISÓRIAS DE AGUA, LUZ , ESGOTO, TELEFONE | C39: 0 | D39: 0 | E39: =D39*C39 -> 0 | G39: CUSTO DE MATERIAL, INSTALAÇÃO DE EQUIPAMENTO, TAXA DE LIGAÇÃO
B40: PLACAS DA OBRA (M²) | C40: 0 | D40: 0 | E40: =D40*C40 -> 0
D41: TOTAL MOB E DESMOB | E41: =SUM(E33:E40) -> 0
B43: EQUIPAMENTO DO CANTEIRO (SE NÃO EXISTIR NA CPU)
B44: DESCRIÇÃO | C44: QNTD | D44: R$ UNTI | E44: R$ TOTAL | G44: DESCRIÇÃO | H44: QNTD | I44: R$ UNTI | J44: R$ TOTAL | K44: O QUE INCLUI?
...

Sheet DIM EQP
B2: QUADRO DE DURAÇÃO DAS ATIVIDADES E RECURSOS
B3: DESCRIÇÃO DO SERVIÇO | C3: UNID. | D3: QTDE | E3: EQUIPE BÁSICA | M3: ÍNDICE DA EQUIPE | O3: JORNADA (h/dia) | P3: DIAS DA EQUIPE BÁSICA | Q3: DURAÇÃO ADOTADA (dias) | R3: QTDE DE EQUIPES | S3: RECURSOS
E4: PED | F4: CARP | G4: ARM | H4: ELET | I4: ENCA | J4: PINT | K4: AJUD | L4: SER | S4: PED | T4: CARP | U4: ARM | V4: ELET | W4: ENCA | X4: PINT | Y4: AJUD | Z4: SER
B5: ='1. BRIEFING'!B14 -> DEMOLIÇÃO E RETIRADA
B6: ='1. BRIEFING'!B15 -> DEMOLIÇÃO DE ALVENARIA DE VEDAÇÃO | C6: ='1. BRIEFING'!C15 -> M² | D6: 100 | L6: 4 | M6: =2.33/L6 -> 0.5825 | N6: h/m³ | O6: 8 | P6: =ROUNDUP(AA6,0) -> 8 | Q6: 0 | R6: =P6/Q6 -> #DIV/0! | S6: =E6*$R6 -> #DIV/0! | T6: =F6*$R6 -> #DIV/0! | U6: =G6*$R6 -> #DIV/0! | V6: =H6*$R6 -> #DIV/0! | W6: =I6*$R6 -> #DIV/0! | X6: =J6*$R6 -> #DIV/0! | Y6: =K6*$R6 -> #DIV/0! | Z6: =L6*$R6 -> #DIV/0! | AA6: =D6/(O6/M6) -> 7.28125
B7: ='1. BRIEFING'!B16 -> REMOÇÃO DE BANCADAS EM GRANITO | C7: ='1. BRIEFING'!C16 -> UND | D7: ='1. BRIEFING'!D16 -> 1,00 | L7: 1 | M7: 0.5 | N7: h/und | O7: 8 | P7: =ROUNDUP(AA7,0) -> 1 | R7: =P7/Q7 -> #DIV/0! | S7: =E7*$R7 -> #DIV/0! | T7: =F7*$R7 -> #DIV/0! | U7: =G7*$R7 -> #DIV/0! | V7: =H7*$R7 -> #DIV/0! | W7: =I7*$R7 -> #DIV/0! | X7: =J7*$R7 -> #DIV/0! | Y7: =K7*$R7 -> #DIV/0! | Z7: =L7*$R7 -> #DIV/0! | AA7: =D7/(O7/M7) -> 0.0625
B8: ='1. BRIEFING'!B17 -> REMOÇÃO DE LOUÇAS E METAIS | C8: ='1. BRIEFING'!C17 -> VB | D8: ='1. BRIEFING'!D17 -> 1,00 | L8: 1 | M8: 0.2 | N8: h/und | O8: 8 | P8: =ROUNDUP(AA8,0) -> 1 | R8: =P8/Q8 -> #DIV/0! | S8: =E8*$R8 -> #DIV/0! | T8: =F8*$R8 -> #DIV/0! | U8: =G8*$R8 -> #DIV/0! | V8: =H8*$R8 -> #DIV/0! | W8: =I8*$R8 -> #DIV/0! | X8: =J8*$R8 -> #DIV/0! | Y8: =K8*$R8 -> #DIV/0! | Z8: =L8*$R8 -> #DIV/0! | AA8: =D8/(O8/M8) -> 0.025
B9: ='1. BRIEFING'!B18 -> REMOÇÃO DE PORTAS INTERNAS EM MADEIRA | C9: ='1. BRIEFING'!C18 -> UN | D9: ='1. BRIEFING'!D18 -> 1,00 | L9: 1 | M9: 0.2 | N9: h/und | O9: 8 | P9: =ROUNDUP(AA9,0) -> 1 | R9: =P9/Q9 -> #DIV/0! | S9: =E9*$R9 -> #DIV/0! | T9: =F9*$R9 -> #DIV/0! | U9: =G9*$R9 -> #DIV/0! | V9: =H9*$R9 -> #DIV/0! | W9: =I9*$R9 -> #DIV/0! | X9: =J9*$R9 -> #DIV/0! | Y9: =K9*$R9 -> #DIV/0! | Z9: =L9*$R9 -> #DIV/0! | AA9: =D9/(O9/M9) -> 0.025
B10: ='1. BRIEFING'!B19 -> DEMOLIÇÃO DE REVESTIMENTO CERÂMICO EM PAREDE | C10: ='1. BRIEFING'!C19 -> M² | D10: ='1. BRIEFING'!D19 -> 1,00 | L10: 1 | M10: 0.72 | N10: h/m² | O10: 8 | P10: =ROUNDUP(AA10,0) -> 1 | R10: =P10/Q10 -> #DIV/0! | S10: =E10*$R10 -> #DIV/0! | T10: =F10*$R10 -> #DIV/0! | U10: =G10*$R10 -> #DIV/0! | V10: =H10*$R10 -> #DIV/0! | W10: =I10*$R10 -> #DIV/0! | X10: =J10*$R10 -> #DIV/0! | Y10: =K10*$R10 -> #DIV/0! | Z10: =L10*$R10 -> #DIV/0! | AA10: =D10/(O10/M10) -> 0.09
B11: ='1. BRIEFING'!B20 -> DEMOLIÇÃO DE REVESTIMENTO CERÂMICO EM PISO | C11: ='1. BRIEFING'!C20 -> M² | D11: ='1. BRIEFING'!D20 -> 1,00 | L11: 1 | M11: 0.72 | N11: h/m² | O11: 8 | P11: =ROUNDUP(AA11,0) -> 1 | R11: =P11/Q11 -> #DIV/0! | S11: =E11*$R11 -> #DIV/0! | T11: =F11*$R11 -> #DIV/0! | U11: =G11*$R11 -> #DIV/0! | V11: =H11*$R11 -> #DIV/0! | W11: =I11*$R11 -> #DIV/0! | X11: =J11*$R11 -> #DIV/0! | Y11: =K11*$R11 -> #DIV/0! | Z11: =L11*$R11 -> #DIV/0! | AA11: =D11/(O11/M11) -> 0.09
B12: ='1. BRIEFING'!B21 -> DEMOLIÇÃO DE FORRO EM GESSO/PVC | C12: ='1. BRIEFING'!C21 -> M² | D12: ='1. BRIEFING'!D21 -> 1,00 | L12: 1 | M12: 0.14 | N12: h/m² | O12: 8 | P12: =ROUNDUP(AA12,0) -> 1 | R12: =P12/Q12 -> #DIV/0! | S12: =E12*$R12 -> #DIV/0! | T12: =F12*$R12 -> #DIV/0! | U12: =G12*$R12 -> #DIV/0! | V12: =H12*$R12 -> #DIV/0! | W12: =I12*$R12 -> #DIV/0! | X12: =J12*$R12 -> #DIV/0! | Y12: =K12*$R12 -> #DIV/0! | Z12: =L12*$R12 -> #DIV/0! | AA12: =D12/(O12/M12) -> 0.0175
B13: ='1. BRIEFING'!B22 -> REMOÇÃO DE LUMINÁRIAS INTERNAS (FORRO) | C13: ='1. BRIEFING'!C22 -> UN | D13: ='1. BRIEFING'!D22 -> 1,00 | L13: 1 | M13: 0.1 | N13: h/und | O13: 8 | P13: =ROUNDUP(AA13,0) -> 1 | R13: =P13/Q13 -> #DIV/0! | S13: =E13*$R13 -> #DIV/0! | T13: =F13*$R13 -> #DIV/0! | U13: =G13*$R13 -> #DIV/0! | V13: =H13*$R13 -> #DIV/0! | W13: =I13*$R13 -> #DIV/0! | X13: =J13*$R13 -> #DIV/0! | Y13: =K13*$R13 -> #DIV/0! | Z13: =L13*$R13 -> #DIV/0! | AA13: =D13/(O13/M13) -> 0.0125
B14: ='1. BRIEFING'!B23 -> REMOÇÃO DOS ENTULHOS POR SACOS E CARRO PEQUENO | C14: ='1. BRIEFING'!C23 -> UN | D14: ='1. BRIEFING'!D23 -> 1,00 | L14: 1 | M14: 0.5 | N14: h/m³ | O14: 8 | P14: =ROUNDUP(AA14,0) -> 1 | R14: =P14/Q14 -> #DIV/0! | S14: =E14*$R14 -> #DIV/0! | T14: =F14*$R14 -> #DIV/0! | U14: =G14*$R14 -> #DIV/0! | V14: =H14*$R14 -> #DIV/0! | W14: =I14*$R14 -> #DIV/0! | X14: =J14*$R14 -> #DIV/0! | Y14: =K14*$R14 -> #DIV/0! | Z14: =L14*$R14 -> #DIV/0! | AA14: =D14/(O14/M14) -> 0.0625
B15: ='1. BRIEFING'!B24 -> SERVIÇO EM ALVENARIA | AA15: =D15/(O15/M15) -> #DIV/0!
B16: ='1. BRIEFING'!B25 -> ASSENTAMENTO DE ALVENARIA DE VEDAÇÃO | C16: ='1. BRIEFING'!C25 -> M² | D16: ='1. BRIEFING'!D25 -> 1 | E16: 1 | L16: 1 | M16: 1.61 | N16: h/m² | O16: 8 | P16: =ROUNDUP(AA16,0) -> 1 | R16: =P16/Q16 -> #DIV/0! | S16: =E16*$R16 -> #DIV/0! | T16: =F16*$R16 -> #DIV/0! | U16: =G16*$R16 -> #DIV/0! | V16: =H16*$R16 -> #DIV/0! | W16: =I16*$R16 -> #DIV/0! | X16: =J16*$R16 -> #DIV/0! | Y16: =K16*$R16 -> #DIV/0! | Z16: =L16*$R16 -> #DIV/0! | AA16: =D16/(O16/M16) -> 0.20125
B17: ='1. BRIEFING'!B29 -> INSTALAÇÃO HIDRÁULICA | AA17: =D17/(O17/M17) -> #DIV/0!
B18: ='1. BRIEFING'!B30 -> INSTALAÇAO DE PONTO DE ÁGUA FRIA | C18: ='1. BRIEFING'!C30 -> UN | D18: ='1. BRIEFING'!D30 -> 10 | M18: 1 | N18: h/und | O18: 8 | P18: =ROUNDUP(AA18,0) -> 2 | R18: =P18/Q18 -> #DIV/0! | S18: =E18*$R18 -> #DIV/0! | T18: =F18*$R18 -> #DIV/0! | U18: =G18*$R18 -> #DIV/0! | V18: =H18*$R18 -> #DIV/0! | W18: =I18*$R18 -> #DIV/0! | X18: =J18*$R18 -> #DIV/0! | Y18: =K18*$R18 -> #DIV/0! | Z18: =L18*$R18 -> #DIV/0! | AA18: =D18/(O18/M18) -> 1.25
B19: ='1. BRIEFING'!B31 -> INSTALAÇÃO DE PONTO DE ESGOTO 50 MM | C19: ='1. BRIEFING'!C31 -> UN | D19: ='1. BRIEFING'!D31 -> 1 | M19: 1 | N19: h/und | O19: 8 | P19: =ROUNDUP(AA19,0) -> 1 | R19: =P19/Q19 -> #DIV/0! | S19: =E19*$R19 -> #DIV/0! | T19: =F19*$R19 -> #DIV/0! | U19: =G19*$R19 -> #DIV/0! | V19: =H19*$R19 -> #DIV/0! | W19: =I19*$R19 -> #DIV/0! | X19: =J19*$R19 -> #DIV/0! | Y19: =K19*$R19 -> #DIV/0! | Z19: =L19*$R19 -> #DIV/0! | AA19: =D19/(O19/M19) -> 0.125
B20: ='1. BRIEFING'!B32 -> RELOCAÇÃO DE PONTO DE ESGOTO 100 MM | C20: ='1. BRIEFING'!C32 -> UN | D20: ='1. BRIEFING'!D32 -> 1 | M20: 1 | N20: h/und | O20: 8 | P20: =ROUNDUP(AA20,0) -> 1 | R20: =P20/Q20 -> #DIV/0! | S20: =E20*$R20 -> #DIV/0! | T20: =F20*$R20 -> #DIV/0! | U20: =G20*$R20 -> #DIV/0! | V20: =H20*$R20 -> #DIV/0! | W20: =I20*$R20 -> #DIV/0! | X20: =J20*$R20 -> #DIV/0! | Y20: =K20*$R20 -> #DIV/0! | Z20: =L20*$R20 -> #DIV/0! | AA20: =D20/(O20/M20) -> 0.125
B21: ='1. BRIEFING'!B33 -> INSTALAÇÃO DE PONTO DE REGISTRO DE GAVETA | C21: ='1. BRIEFING'!C33 -> UN | D21: ='1. BRIEFING'!D33 -> 1 | M21: 1 | N21: h/und | O21: 8 | P21: =ROUNDUP(AA21,0) -> 1 | R21: =P21/Q21 -> #DIV/0! | S21: =E21*$R21 -> #DIV/0! | T21: =F21*$R21 -> #DIV/0! | U21: =G21*$R21 -> #DIV/0! | V21: =H21*$R21 -> #DIV/0! | W21: =I21*$R21 -> #DIV/0! | X21: =J21*$R21 -> #DIV/0! | Y21: =K21*$R21 -> #DIV/0! | Z21: =L21*$R21 -> #DIV/0! | AA21: =D21/(O21/M21) -> 0.125
B22: ='1. BRIEFING'!B34 -> INSTALAÇÃO DE PONTO DE REGISTRO DE PRESSÃO | C22: ='1. BRIEFING'!C34 -> UN | D22: ='1. BRIEFING'!D34 -> 1 | M22: 1 | N22: h/und | O22: 8 | P22: =ROUNDUP(AA22,0) -> 1 | R22: =P22/Q22 -> #DIV/0! | S22: =E22*$R22 -> #DIV/0! | T22: =F22*$R22 -> #DIV/0! | U22: =G22*$R22 -> #DIV/0! | V22: =H22*$R22 -> #DIV/0! | W22: =I22*$R22 -> #DIV/0! | X22: =J22*$R22 -> #DIV/0! | Y22: =K22*$R22 -> #DIV/0! | Z22: =L22*$R22 -> #DIV/0! | AA22: =D22/(O22/M22) -> 0.125
B23: ='1. BRIEFING'!B35 -> INSTALAÇÃO ELÉTRICA | AA23: =D23/(O23/M23) -> #DIV/0!
B24: ='1. BRIEFING'!B36 -> INSTALAÇÃO DE INFRAESTRUTURA PARA TOMADA E ILUMINAÇÃO | C24: ='1. BRIEFING'!C36 -> UN | D24: ='1. BRIEFING'!D36 -> 1 | M24: 0.2 | N24: h/und | O24: 8 | P24: =ROUNDUP(AA24,0) -> 1 | R24: =P24/Q24 -> #DIV/0! | S24: =E24*$R24 -> #DIV/0! | T24: =F24*$R24 -> #DIV/0! | U24: =G24*$R24 -> #DIV/0! | V24: =H24*$R24 -> #DIV/0! | W24: =I24*$R24 -> #DIV/0! | X24: =J24*$R24 -> #DIV/0! | Y24: =K24*$R24 -> #DIV/0! | Z24: =L24*$R24 -> #DIV/0! | AA24: =D24/(O24/M24) -> 0.025
B25: ='1. BRIEFING'!B37 -> INSTALAÇÃO DE CABEAMENTO PARA PONTOS DE TOMADAS | C25: ='1. BRIEFING'!C37 -> UN | D25: ='1. BRIEFING'!D37 -> 1 | M25: 0.2 | N25: h/und | O25: 8 | P25: =ROUNDUP(AA25,0) -> 1 | R25: =P25/Q25 -> #DIV/0! | S25: =E25*$R25 -> #DIV/0! | T25: =F25*$R25 -> #DIV/0! | U25: =G25*$R25 -> #DIV/0! | V25: =H25*$R25 -> #DIV/0! | W25: =I25*$R25 -> #DIV/0! | X25: =J25*$R25 -> #DIV/0! | Y25: =K25*$R25 -> #DIV/0! | Z25: =L25*$R25 -> #DIV/0! | AA25: =D25/(O25/M25) -> 0.025
B26: ='1. BRIEFING'!B38 -> INSTALAÇÃO DE CABEAMENTO PARA PONTOS DE ILUMINAÇÃO | C26: ='1. BRIEFING'!C38 -> UN | D26: ='1. BRIEFING'!D38 -> 1 | M26: 0.2 | N26: h/und | O26: 8 | P26: =ROUNDUP(AA26,0) -> 1 | R26: =P26/Q26 -> #DIV/0! | S26: =E26*$R26 -> #DIV/0! | T26: =F26*$R26 -> #DIV/0! | U26: =G26*$R26 -> #DIV/0! | V26: =H26*$R26 -> #DIV/0! | W26: =I26*$R26 -> #DIV/0! | X26: =J26*$R26 -> #DIV/0! | Y26: =K26*$R26 -> #DIV/0! | Z26: =L26*$R26 -> #DIV/0! | AA26: =D26/(O26/M26) -> 0.025
B27: ='1. BRIEFING'!B39 -> REISNTALAÇÃO DE QUADRO DE DISTRIBUIÇÃO (ADEQUAÇÃO) | C27: ='1. BRIEFING'!C39 -> VB | D27: ='1. BRIEFING'!D39 -> 1 | M27: 0.2 | N27: h/und | O27: 8 | P27: =ROUNDUP(AA27,0) -> 1 | R27: =P27/Q27 -> #DIV/0! | S27: =E27*$R27 -> #DIV/0! | T27: =F27*$R27 -> #DIV/0! | U27: =G27*$R27 -> #DIV/0! | V27: =H27*$R27 -> #DIV/0! | W27: =I27*$R27 -> #DIV/0! | X27: =J27*$R27 -> #DIV/0! | Y27: =K27*$R27 -> #DIV/0! | Z27: =L27*$R27 -> #DIV/0! | AA27: =D27/(O27/M27) -> 0.025
B28: ='1. BRIEFING'!B40 -> INSTALAÇÃO DE INFRAESTRUTURA PARA PONTOS DE REDE/ANTENA/CAMERA/SOM | C28: ='1. BRIEFING'!C40 -> UN | D28: ='1. BRIEFING'!D40 -> 1 | M28: 0.2 | N28: h/und | O28: 8 | P28: =ROUNDUP(AA28,0) -> 1 | R28: =P28/Q28 -> #DIV/0! | S28: =E28*$R28 -> #DIV/0! | T28: =F28*$R28 -> #DIV/0! | U28: =G28*$R28 -> #DIV/0! | V28: =H28*$R28 -> #DIV/0! | W28: =I28*$R28 -> #DIV/0! | X28: =J28*$R28 -> #DIV/0! | Y28: =K28*$R28 -> #DIV/0! | Z28: =L28*$R28 -> #DIV/0! | AA28: =D28/(O28/M28) -> 0.025
B29: ='1. BRIEFING'!B41 -> INSTALAÇÃO DE EQUIPAMENTOS | AA29: =D29/(O29/M29) -> #DIV/0!
B30: ='1. BRIEFING'!B42 -> INSTALAÇÃO DE INFRA PARA AR CONDICIONADO | C30: ='1. BRIEFING'!C39 -> VB | D30: ='1. BRIEFING'!D39 -> 1 | N30: h/und | O30: 8 | P30: =ROUNDUP(AA30,0) -> #DIV/0! | R30: =P30/Q30 -> #DIV/0! | S30: =E30*$R30 -> #DIV/0! | T30: =F30*$R30 -> #DIV/0! | U30: =G30*$R30 -> #DIV/0! | V30: =H30*$R30 -> #DIV/0! | W30: =I30*$R30 -> #DIV/0! | X30: =J30*$R30 -> #DIV/0! | Y30: =K30*$R30 -> #DIV/0! | Z30: =L30*$R30 -> #DIV/0! | AA30: =D30/(O30/M30) -> #DIV/0!
B31: ='1. BRIEFING'!B43 -> INSTALAÇÃO DE BOILER | C31: ='1. BRIEFING'!C40 -> UN | D31: ='1. BRIEFING'!D40 -> 1 | N31: h/und | O31: 8 | P31: =ROUNDUP(AA31,0) -> #DIV/0! | R31: =P31/Q31 -> #DIV/0! | S31: =E31*$R31 -> #DIV/0! | T31: =F31*$R31 -> #DIV/0! | U31: =G31*$R31 -> #DIV/0! | V31: =H31*$R31 -> #DIV/0! | W31: =I31*$R31 -> #DIV/0! | X31: =J31*$R31 -> #DIV/0! | Y31: =K31*$R31 -> #DIV/0! | Z31: =L31*$R31 -> #DIV/0! | AA31: =D31/(O31/M31) -> #DIV/0!
B32: ='1. BRIEFING'!B44 -> INSTALAÇÃO DE EXAUSTOR l BWC CAMARIM E MAS | C32: ='1. BRIEFING'!C41 -> 0 | D32: ='1. BRIEFING'!D41 -> 0 | N32: h/und | O32: 8 | P32: =ROUNDUP(AA32,0) -> #DIV/0! | R32: =P32/Q32 -> #DIV/0! | S32: =E32*$R32 -> #DIV/0! | T32: =F32*$R32 -> #DIV/0! | U32: =G32*$R32 -> #DIV/0! | V32: =H32*$R32 -> #DIV/0! | W32: =I32*$R32 -> #DIV/0! | X32: =J32*$R32 -> #DIV/0! | Y32: =K32*$R32 -> #DIV/0! | Z32: =L32*$R32 -> #DIV/0! | AA32: =D32/(O32/M32) -> #DIV/0!
B33: ='1. BRIEFING'!B45 -> INSTALAÇÃO DE ILUMINAÇÃO | AA33: =D33/(O33/M33) -> #DIV/0!
B34: ='1. BRIEFING'!B46 -> INSTALAÇÃO DE LUMINÁRIA DE EMBUTIR QUADRADA 20W EM FORRO DE GESSO | C34: ='1. BRIEFING'!C43 -> UN | D34: ='1. BRIEFING'!D43 -> 1 | O34: 8 | P34: =ROUNDUP(AA34,0) -> #DIV/0! | R34: =P34/Q34 -> #DIV/0! | S34: =E34*$R34 -> #DIV/0! | T34: =F34*$R34 -> #DIV/0! | U34: =G34*$R34 -> #DIV/0! | V34: =H34*$R34 -> #DIV/0! | W34: =I34*$R34 -> #DIV/0! | X34: =J34*$R34 -> #DIV/0! | Y34: =K34*$R34 -> #DIV/0! | Z34: =L34*$R34 -> #DIV/0! | AA34: =D34/(O34/M34) -> #DIV/0!
B35: ='1. BRIEFING'!B47 -> INSTALAÇÃO DE DICROICAS DIRECIONAIS | C35: ='1. BRIEFING'!C44 -> UN | D35: ='1. BRIEFING'!D44 -> 1 | O35: 8 | P35: =ROUNDUP(AA35,0) -> #DIV/0! | R35: =P35/Q35 -> #DIV/0! | S35: =E35*$R35 -> #DIV/0! | T35: =F35*$R35 -> #DIV/0! | U35: =G35*$R35 -> #DIV/0! | V35: =H35*$R35 -> #DIV/0! | W35: =I35*$R35 -> #DIV/0! | X35: =J35*$R35 -> #DIV/0! | Y35: =K35*$R35 -> #DIV/0! | Z35: =L35*$R35 -> #DIV/0! | AA35: =D35/(O35/M35) -> #DIV/0!
B36: ='1. BRIEFING'!B48 -> INSTALAÇÃO DE FITA EM LED | C36: ='1. BRIEFING'!C45 -> 0 | D36: ='1. BRIEFING'!D45 -> 0 | O36: 8 | P36: =ROUNDUP(AA36,0) -> #DIV/0! | R36: =P36/Q36 -> #DIV/0! | S36: =E36*$R36 -> #DIV/0! | T36: =F36*$R36 -> #DIV/0! | U36: =G36*$R36 -> #DIV/0! | V36: =H36*$R36 -> #DIV/0! | W36: =I36*$R36 -> #DIV/0! | X36: =J36*$R36 -> #DIV/0! | Y36: =K36*$R36 -> #DIV/0! | Z36: =L36*$R36 -> #DIV/0! | AA36: =D36/(O36/M36) -> #DIV/0!
B37: ='1. BRIEFING'!B49 -> INSTALAÇÃO DE PENDENTE | C37: ='1. BRIEFING'!C46 -> UN | D37: ='1. BRIEFING'!D46 -> 1 | O37: 8 | P37: =ROUNDUP(AA37,0) -> #DIV/0! | R37: =P37/Q37 -> #DIV/0! | S37: =E37*$R37 -> #DIV/0! | T37: =F37*$R37 -> #DIV/0! | U37: =G37*$R37 -> #DIV/0! | V37: =H37*$R37 -> #DIV/0! | W37: =I37*$R37 -> #DIV/0! | X37: =J37*$R37 -> #DIV/0! | Y37: =K37*$R37 -> #DIV/0! | Z37: =L37*$R37 -> #DIV/0! | AA37: =D37/(O37/M37) -> #DIV/0!
B38: ='1. BRIEFING'!B54 -> SERVIÇO EM FORRO | AA38: =D38/(O38/M38) -> #DIV/0!
B39: ='1. BRIEFING'!B55 -> FORNECIMENTO E INSTALAÇÃO DE FORRO EM GESSO | C39: ='1. BRIEFING'!C48 -> UN | D39: ='1. BRIEFING'!D48 -> 1 | O39: 8 | P39: =ROUNDUP(AA39,0) -> #DIV/0! | R39: =P39/Q39 -> #DIV/0! | S39: =E39*$R39 -> #DIV/0! | T39: =F39*$R39 -> #DIV/0! | U39: =G39*$R39 -> #DIV/0! | V39: =H39*$R39 -> #DIV/0! | W39: =I39*$R39 -> #DIV/0! | X39: =J39*$R39 -> #DIV/0! | Y39: =K39*$R39 -> #DIV/0! | Z39: =L39*$R39 -> #DIV/0! | AA39: =D39/(O39/M39) -> #DIV/0!
B40: ='1. BRIEFING'!B56 -> FORNECIMENTO E INSTALAÇÃO DE JUNTA EM DILATAÇÃO 3X3 CM | C40: ='1. BRIEFING'!C49 -> UN | D40: ='1. BRIEFING'!D49 -> 1 | O40: 8 | P40: =ROUNDUP(AA40,0) -> #DIV/0! | R40: =P40/Q40 -> #DIV/0! | S40: =E40*$R40 -> #DIV/0! | T40: =F40*$R40 -> #DIV/0! | U40: =G40*$R40 -> #DIV/0! | V40: =H40*$R40 -> #DIV/0! | W40: =I40*$R40 -> #DIV/0! | X40: =J40*$R40 -> #DIV/0! | Y40: =K40*$R40 -> #DIV/0! | Z40: =L40*$R40 -> #DIV/0! | AA40: =D40/(O40/M40) -> #DIV/0!
B41: ='1. BRIEFING'!B57 -> FORNECIMENTO E INSTALAÇÃO DE CORTINEIRO | C41: ='1. BRIEFING'!C50 -> UN | D41: ='1. BRIEFING'!D50 -> 1 | O41: 8 | P41: =ROUNDUP(AA41,0) -> #DIV/0! | R41: =P41/Q41 -> #DIV/0! | S41: =E41*$R41 -> #DIV/0! | T41: =F41*$R41 -> #DIV/0! | U41: =G41*$R41 -> #DIV/0! | V41: =H41*$R41 -> #DIV/0! | W41: =I41*$R41 -> #DIV/0! | X41: =J41*$R41 -> #DIV/0! | Y41: =K41*$R41 -> #DIV/0! | Z41: =L41*$R41 -> #DIV/0! | AA41: =D41/(O41/M41) -> #DIV/0!
...

Sheet 0. P. VENDA
B3: RESUMO ORÇAMENTO | H3: DESTRINCHADO
A4: 1 | B4: CUSTO DIRETO | C4: ='4. PLAN ORÇA'!M94 -> 28880.24 | D4: =C4/C7 -> 1 | H4: PREÇO DE VENDA | I4: =C27 -> 39662.196
A5: 2 | B5: CUSTO INDIRETO | C5: ='4. CUSTO IND'!H2 -> 0 | D5: =C5/C7 -> 0
H6: COMISSÃO | I6: =I4*J6 -> 396.62196 | J6: 0.01
A7: 3 | B7: TOTAL CD+CI | C7: =SUM(C4,C5) -> 28880.24
H8: TRIBUTOS | I8: =I4*C22 -> 1983.1098 | J8: =C22 -> 0.05
A9: 4 | B9: ADM CENTRAL | C9: =C7*D9 -> 288.8024 | D9: 0.01 | E9: =SUM(C9:C11) -> 866.4072
A10: 5 | B10: CUSTO FINANC. | C10: =C7*D10 -> 288.8024 | D10: 0.01 | H10: LUCRO | I10: =(I4*C24)-I6 -> 7535.8173 | J10: =I10/I4 -> 0.19
A11: 6 | B11: IC SOBRE CD+CI | C11: =C7*D11 -> 288.8024 | D11: 0.01
H12: SALDO CUSTO | I12: =I4-I6-I8-I10 -> 29746.647 | J12: =I12/I4 -> 0.75
A13: 7 | B13: TOTAL CUSTO | C13: =SUM(C7+C9+C10+C11) -> 29746.647
H14: ADM CENTRAL | I14: =I12*D9 -> 297.46647
A15: 8 | B15: COFINS | C15: 0.015 | D15: =$C$27*C15 -> 594.93294 | H15: CUSTO FINANC | I15: =I12*D10 -> 297.46647
A16: 9 | B16: PIS | C16: 0 | D16: =$C$27*C16 -> 0 | H16: IMPREV E CONTIG | I16: =I12*D11 -> 297.46647
A17: 10 | B17: ICMS | C17: 0 | D17: =$C$27*C17 -> 0
A18: 11 | B18: ISS | C18: 0.02 | D18: =$C$27*C18 -> 793.24393 | H18: SALDO CUSTO | I18: =I12-(I14+I15+I16) -> 28854.248
A19: 12 | B19: IRPJ | C19: 0 | D19: =$C$27*C19 -> 0
A20: 13 | B20: CSLL | C20: 0.015 | D20: =$C$27*C20 -> 594.93294 | H20: CUSTO INDIRETO | I20: =I18*D5 -> 0 | J20: =I20/I18 -> 0
H21: CUSTO DIRETO | I21: =I18*D4 -> 28854.248 | J21: =I21/I18 -> 1
A22: 14 | B22: ALÍQUOTA % | C22: =SUM(C15:C20) -> 0.05 | D22: =SUM(D15:D20) -> 1983.1098 | E22: FAT ATÉ 180 K
H23: SALDO | I23: =I18-(I20+I21) -> 0
A24: 15 | B24: LUCRO | C24: 0.2 | D24: =C27*C24 -> 7932.4393 | E24: LUCRO LIQUIDO
A25: 16 | B25: IMPOST + LUCRO | C25: =SUM(C22,C24) -> 0.25 | D25: =SUM(D22+D24) -> 9915.5491
A27: 17 | B27: PREÇO DE VENDA | C27: =C13/(1-C25) -> 39662.196 | E27: UND
A28: 18 | B28: BDI | C28: =C27/C13-1 -> 0.33333333

Sheet PLANEJ FIN
B2: CRONOGRAMA FISICO-FINANCEIRO
D4: 05 - 08 DEZ | F4: 11 - 15 DEZ | H4: 18 - 22 DEZ | J4: GERAL
B5: CÓDIGO | C5: SERVIÇOS | D5: VALOR (R$) | E5: PERC. (%) | F5: VALOR (R$) | G5: PERC. (%) | H5: VALOR (R$) | I5: PERC. (%) | J5: TOTAL (%) | K5: VALOR (R$) | L5: VALOR C/ BDI (R$) | M5: PERC. (%)
C6: DESPESA ADMINISTRATIVA | D6: =L6*E6/100 -> #REF! | E6: 100 | J6: =E6+G6 -> 100 | K6: ='[1]R$ OBRA'!G19 -> #REF! | L6: =K6*1.4 -> #REF! | M6: =L6/$L$21 -> #REF!
B7: 1 | C7: ELETRICA
B8: 2 | C8: PONTO DE TOMADA RESIDENCIAL INCLUINDO TOMADA 10A/250V, CAIXA ELÉTRICA ELETRODUTO, CABO, RASGO, QUEBRA E CHUMBAMENTO. | D8: =L8*E8/100 -> #REF! | E8: 50 | F8: =$L8*G8/100 -> #REF! | G8: 0 | H8: =$L8*I8/100 -> #REF! | I8: 0 | J8: =E8+G8 -> 50 | K8: ='[1]R$ OBRA'!G29 -> #REF! | L8: =K8*1.4 -> #REF! | M8: =L8/$L$21 -> #REF!
B9: 3 | C9: REVESTIMENTO
B10: 4 | C10: REVESTIMENTO CERÂMICO PARA PISO COM PLACAS TIPO ESMALTADA EXTRA DE DIMENSÕES 35X35 CM APLICADA EM AMBIENTES DE ÁREA ENTRE 5 M2 E 10 M2 | D10: =L10*E10/100 -> #REF! | E10: 100 | F10: =$L10*G10/100 -> #REF! | G10: 0 | H10: =$L10*I10/100 -> #REF! | I10: 0 | J10: =E10+G10 -> 100 | K10: ='[1]R$ OBRA'!G49 -> #REF! | L10: =K10*1.4 -> #REF! | M10: =L10/$L$21 -> #REF!
B11: 5 | C11: PINTURA
B12: 6 | C12: APLICAÇÃO E LIXAMENTO DE MASSA LÁTEX EM PAREDES, DUAS DEMÃOS. | D12: =L12*E12/100 -> #VALUE! | E12: 0 | F12: =$L12*G12/100 -> #VALUE! | G12: 100 | H12: =$L12*I12/100 -> #VALUE! | I12: 100 | J12: =E12+G12 -> 100 | K12: #REF! | L12: =K12*1.4 -> #VALUE! | M12: =L12/$L$21 -> #VALUE!
B13: 7 | C13: APLICAÇÃO MANUAL DE PINTURA COM TINTA LÁTEX ACRÍLICA EM PAREDES, DUAS DEMÃOS. | D13: =L13*E13/100 -> #VALUE! | E13: 0 | F13: =$L13*G13/100 -> #VALUE! | G13: 100 | H13: =$L13*I13/100 -> #VALUE! | I13: 100 | J13: =E13+G13 -> 100 | K13: #REF! | L13: =K13*1.4 -> #VALUE! | M13: =L13/$L$21 -> #VALUE!
B14: 8 | C14: LIMPEZA FINAL
B15: 9 | C15: LIMPEZA FINAL DA OBRA | D15: =L15*E15/100 -> #VALUE! | E15: 0 | F15: =$L15*G15/100 -> #VALUE! | G15: 100 | H15: =$L15*I15/100 -> #VALUE! | I15: 100 | J15: =E15+G15 -> 100 | K15: #REF! | L15: =K15*1.4 -> #VALUE! | M15: =L15/$L$21 -> #VALUE!
B16: 10 | C16: RETIRADA DE ENTULHO | D16: =L16*E16/100 -> #VALUE! | E16: 0 | F16: =$L16*G16/100 -> #VALUE! | G16: 0 | H16: =$L16*I16/100 -> #VALUE! | I16: 0 | J16: =E16+G16 -> 0 | K16: #REF! | L16: =K16 -> #REF! | M16: =L16/$L$21 -> #VALUE!
B18: TOTAIS SEMANA (R$) | D18: =SUM(D6:D16) -> #REF! | F18: =SUM(G7:G16) -> 300 | H18: =SUM(I7:I16) -> 300
B19: PORCENTAGEM SEMANA (%) | D19: =D18/$L$21 -> #REF! | F19: =G18/$L$21 -> #REF! | H19: =I18/$L$21 -> #REF!
B20: TOTAIS ACUMULADOS (R$) | D20: =D18 -> #REF! | F20: =G18+E20 -> 0 | H20: =I18+G20 -> 0
B21: PORCENTAGEM ACUMULADAS (%) | D21: =D19 -> #REF! | F21: =G19+E21 -> 0 | H21: =I19+G21 -> 0 | K21: =SUM(K6:K16) -> #REF! | L21: =SUM(L6:L16) -> #REF! | M21: =SUM(M6:M16) -> #REF!
